phoenix-srun: job 486770 queued and waiting for resources
phoenix-srun: job 486770 has been allocated resources
phoenix-srun: Job 486770 scheduled successfully!
Current QUOTA_TYPE is [reserved], which means the job has occupied quota in RESERVED_TOTAL under your partition.
Current PHX_PRIORITY is normal

[_init_petrel]-   1  cur: 0.000s, avg(1): 0.000s
[rank 0000]-[INFO]-[6bd7]-[2022-10-31 04:26:13]-[/spring/src/linklink/src/core.cc:220]: linklink init: world_size=1, rank=(0,0), device_num=1, thread_pool=1, buffer_pool=-1
[rank 0] >> task_info.group[0] ranks [0]
[rank 0] >> task_info.root_group ranks [0]
[rank 0] >> task_info.backbone_share_group[[0]] ranks [0]
[rank 0] >> task_info.neck_share_group[[0]] ranks [0]
[rank 0] >> task_info.decoder_share_group[[0]] ranks [0]
[rank 0] backbone of task0 has been overided to {'type': 'vit_base_patch16_ladder_attention_share_pos_embed', 'kwargs': {'task_sp_list': ['rel_pos_h', 'rel_pos_w'], 'pretrained': True, 'img_size': [224, 224], 'lms_checkpoint_train': 'fairscale', 'window': False, 'test_pos_mode': 'learnable_simple_interpolate', 'pad_attn_mask': False, 'round_padding': True, 'learnable_pos': True, 'drop_path_rate': 0.3}}
[rank 0] neck of task0 has been overided to {'type': 'LadderSideAttentionFPN', 'kwargs': {'lms_checkpoint_train': 'fairscale', 'layer_feat_nums': 12, 'hidden_dim': 768, 'reduct_ration': 8, 'transformer_block_nums': 1, 'transformer_block_num_heads': 2, 'gate_T': 1.0, 'gate_alpha': 0}}
[rank 0] decoder of task0 has been overided to {'type': 'ViT_SimpleUpSampling', 'kwargs': {'task': 'par', 'input_size': [480, 480], 'in_channels': 768, 'num_classes': 20, 'bn_type': 'LN', 'loss_cfg': {'type': 'FSCELoss', 'kwargs': {'configer': {'ce_reduction': 'elementwise_mean', 'ce_ignore_index': 255}}}}}
[rank 0] dataset of task0 has been overided to {'type': 'CIHPParsingDataset', 'kwargs': {'data_path': 'sh1424:s3://parsing_public/CIHP', 'data_use_ratio': 1, 'cfg': {'is_flip': True, 'crop_size': [480, 480], 'is_multi_scale': True, 'scale_factor': 11, 'center_crop_test': False, 'base_size': 480, 'eval_crop_size': [480, 480], 'ignore_value': 255, 'num_classes': 20, 'label_list': [0, 1, 2, 3, 4, 5, 6, 7, 8, 9, 10, 11, 12, 13, 14, 15, 16, 17, 18, 19]}}}
[rank 0] sampler of task0 has been overided to {'batch_size': 24, 'shuffle_strategy': 1}
[rank 0] >> task_info.group[0] ranks [0]
[rank 0] >> task_info.root_group ranks [0]
[rank 0] >> task_info.backbone_share_group[[0]] ranks [0]
[rank 0] >> task_info.neck_share_group[[0]] ranks [0]
[rank 0] >> task_info.decoder_share_group[[0]] ranks [0]
[rank 0] dataset of task0 has been overided to {'type': 'CIHPParsingDataset', 'kwargs': {'data_path': 'shlg:s3://parsing_public/CIHP', 'data_use_ratio': 1, 'dataset': 'val', 'is_train': False, 'cfg': {'eval_crop_size': [480, 480], 'is_flip': False, 'is_multi_scale': False, 'ignore_value': 255, 'num_classes': 20, 'label_list': [0, 1, 2, 3, 4, 5, 6, 7, 8, 9, 10, 11, 12, 13, 14, 15, 16, 17, 18, 19]}}}
[rank 0] sampler of task0 has been overided to {'batch_size': 4}
2022-10-31 16:26:16 7d2fac4f SUCCESS: (pavi2.training) SummaryWriter is initialized, remember to close the SummaryWriter at the end of your program.

PAVI Info ###################################
Training：v100_32g_vitbase_size224_lr1e3_stepLRx3_bmp1_adafactor_wd01_clip05_layerdecay075_lpe_peddet_citypersons_LSA_reduct8_tbn1_heads2_gate1_peddetShareDecoder_exp3_setting_SharePosEmbed
Project：parsing_test
Training_id：123638
Training_url：http://autolink.parrots.sensetime.com/pages/content/project/3567/training/123638
Warning: If `Training_url` is not accessible, please upgrade your pavi version.
#############################################

sync_print: rank 0, override tensor.cuda() to preserve task_specific flag
[2022-10-31 16:26:18,007][solver_multitask_dev.py][line: 682][    INFO] deterministic mode, seed: 2022, worker_rank: True,                                   cudnn_deterministic: False
[rank 0] config[kwargs] {'data_path': 'shlg:s3://parsing_public/CIHP', 'data_use_ratio': 1, 'cfg': {'is_flip': False, 'crop_size': [480, 480], 'is_multi_scale': False, 'scale_factor': 11, 'center_crop_test': False, 'base_size': 480, 'eval_crop_size': [480, 480], 'ignore_value': 255, 'num_classes': 20, 'label_list': [0, 1, 2, 3, 4, 5, 6, 7, 8, 9, 10, 11, 12, 13, 14, 15, 16, 17, 18, 19]}, 'dataset': 'val', 'is_train': False, 'ginfo': {'group': 1, 'task_size': 1, 'task_id': 0, 'task_rank': 0, 'task_root_rank': 0, 'root_group': 2, 'task_sizes': [1], 'task_root_ranks': [0], 'task_num': 1, 'backbone_share_group': 3, 'backbone_group_size': 1, 'backbone_task_size': 1, 'backbone_task_rank': 0, 'neck_share_group': 4, 'neck_group_size': 1, 'neck_task_size': 1, 'neck_task_rank': 0, 'decoder_share_group': 5, 'decoder_group_size': 1, 'decoder_task_size': 1, 'decoder_task_rank': 0, 'task_name': 'parsing_cihp', 'task_names': ['parsing_cihp'], 'task_weight': 1.0, 'task_type': 'normal', 'task_types': ['normal'], 'task_random_seed': 0}}
2022-10-31 16:27:28,403 ERR [MainProcess] [MainThread] - Get operation (shlg:s3://parsing_public/CIHP/instance-level_human_parsing/Validation/val_id.txt) has tried 10 times and failed: Could not connect to the endpoint URL: "http://10.198.32.254:80/parsing_public/CIHP/instance-level_human_parsing/Validation/val_id.txt" [P:154042 T:139630267361088 F:io_retry.py:36]
Traceback (most recent call last):
  File "/mnt/cache/chencheng1/.local/lib/python3.6/site-packages/urllib3/connection.py", line 171, in _new_conn
    (self._dns_host, self.port), self.timeout, **extra_kw)
  File "/mnt/cache/chencheng1/.local/lib/python3.6/site-packages/urllib3/util/connection.py", line 79, in create_connection
    raise err
  File "/mnt/cache/chencheng1/.local/lib/python3.6/site-packages/urllib3/util/connection.py", line 69, in create_connection
    sock.connect(sa)
ConnectionRefusedError: [Errno 111] Connection refused

During handling of the above exception, another exception occurred:

Traceback (most recent call last):
  File "/mnt/cache/chencheng1/.local/lib/python3.6/site-packages/botocore/httpsession.py", line 242, in send
    decode_content=False,
  File "/mnt/cache/chencheng1/.local/lib/python3.6/site-packages/urllib3/connectionpool.py", line 638, in urlopen
    _stacktrace=sys.exc_info()[2])
  File "/mnt/cache/chencheng1/.local/lib/python3.6/site-packages/urllib3/util/retry.py", line 343, in increment
    raise six.reraise(type(error), error, _stacktrace)
  File "/mnt/cache/chencheng1/.local/lib/python3.6/site-packages/urllib3/packages/six.py", line 686, in reraise
    raise value
  File "/mnt/cache/chencheng1/.local/lib/python3.6/site-packages/urllib3/connectionpool.py", line 600, in urlopen
    chunked=chunked)
  File "/mnt/cache/chencheng1/.local/lib/python3.6/site-packages/urllib3/connectionpool.py", line 354, in _make_request
    conn.request(method, url, **httplib_request_kw)
  File "/mnt/cache/share/spring/conda_envs/miniconda3/envs/s0.3.4/lib/python3.6/http/client.py", line 1254, in request
    self._send_request(method, url, body, headers, encode_chunked)
  File "/mnt/cache/chencheng1/.local/lib/python3.6/site-packages/botocore/awsrequest.py", line 125, in _send_request
    method, url, body, headers, *args, **kwargs)
  File "/mnt/cache/share/spring/conda_envs/miniconda3/envs/s0.3.4/lib/python3.6/http/client.py", line 1300, in _send_request
    self.endheaders(body, encode_chunked=encode_chunked)
  File "/mnt/cache/share/spring/conda_envs/miniconda3/envs/s0.3.4/lib/python3.6/http/client.py", line 1249, in endheaders
    self._send_output(message_body, encode_chunked=encode_chunked)
  File "/mnt/cache/chencheng1/.local/lib/python3.6/site-packages/botocore/awsrequest.py", line 152, in _send_output
    self.send(msg)
  File "/mnt/cache/chencheng1/.local/lib/python3.6/site-packages/botocore/awsrequest.py", line 236, in send
    return super(AWSConnection, self).send(str)
  File "/mnt/cache/share/spring/conda_envs/miniconda3/envs/s0.3.4/lib/python3.6/http/client.py", line 974, in send
    self.connect()
  File "/mnt/cache/chencheng1/.local/lib/python3.6/site-packages/urllib3/connection.py", line 196, in connect
    conn = self._new_conn()
  File "/mnt/cache/chencheng1/.local/lib/python3.6/site-packages/urllib3/connection.py", line 180, in _new_conn
    self, "Failed to establish a new connection: %s" % e)
urllib3.exceptions.NewConnectionError: <botocore.awsrequest.AWSHTTPConnection object at 0x7efc7d4824a8>: Failed to establish a new connection: [Errno 111] Connection refused

During handling of the above exception, another exception occurred:

Traceback (most recent call last):
  File "../../..//test.py", line 99, in <module>
    main()
  File "../../..//test.py", line 91, in main
    S.initialize(args)
  File "/mnt/cache/chencheng1/vitruvian/vitruvian-multitask/core/solvers/solver_multitask_dev.py", line 688, in initialize
    self.create_dataset()
  File "/mnt/cache/chencheng1/vitruvian/vitruvian-multitask/core/solvers/solver_multitask_dev.py", line 215, in create_dataset
    self.dataset = datasets.dataset_entry(self.config.dataset)
  File "/mnt/cache/chencheng1/vitruvian/vitruvian-multitask/core/data/datasets/__init__.py", line 17, in dataset_entry
    return globals()[config['type']](**config['kwargs'])
  File "/mnt/cache/chencheng1/vitruvian/vitruvian-multitask/core/data/datasets/images/parsing_dataset.py", line 598, in __init__
    cfg=cfg, **kwargs)
  File "/mnt/cache/chencheng1/vitruvian/vitruvian-multitask/core/data/datasets/images/parsing_dataset.py", line 150, in __init__
    self.img_list, self.label_list, self.name_list = self._list_dirs(data_path)
  File "/mnt/cache/chencheng1/vitruvian/vitruvian-multitask/core/data/datasets/images/parsing_dataset.py", line 630, in _list_dirs
    list_lines = s3client.Get(list_txt)
  File "/mnt/cache/chencheng1/.local/lib/python3.6/site-packages/petrel_client/client.py", line 48, in get
    data, _ = self.get_with_info(*args, **kwargs)
  File "/mnt/cache/chencheng1/.local/lib/python3.6/site-packages/petrel_client/client.py", line 45, in get_with_info
    return self._get_local_client().get_with_info(uri, **kwargs)
  File "/mnt/cache/chencheng1/.local/lib/python3.6/site-packages/petrel_client/mixed_client.py", line 182, in get_with_info
    return do_get_with_info(self, uri, **kwargs)
  File "/mnt/cache/chencheng1/.local/lib/python3.6/site-packages/petrel_client/common/io_retry.py", line 16, in new_fn
    return _retry(op_name, exceptions, raises, tries, fn, self, *args, **kwargs)
  File "/mnt/cache/chencheng1/.local/lib/python3.6/site-packages/petrel_client/common/io_retry.py", line 26, in _retry
    return fn(client, *args, **kwargs)
  File "/mnt/cache/chencheng1/.local/lib/python3.6/site-packages/petrel_client/mixed_client.py", line 172, in do_get_with_info
    return self._get_with_info(uri, **kwargs)
  File "/mnt/cache/chencheng1/.local/lib/python3.6/site-packages/petrel_client/mixed_client.py", line 148, in _get_with_info
    content, info = get_fn(**kwargs)
  File "/mnt/cache/chencheng1/.local/lib/python3.6/site-packages/petrel_client/mixed_client.py", line 67, in io_fn
    return client.get_with_info(cluster, bucket, key, **kwargs)
  File "/mnt/cache/chencheng1/.local/lib/python3.6/site-packages/petrel_client/common/io_profile.py", line 141, in new_fn
    return _profile(op_name, fn, self, *args, **kwargs)
  File "/mnt/cache/chencheng1/.local/lib/python3.6/site-packages/petrel_client/common/io_profile.py", line 151, in _profile
    ret = fn(client, *args, **kwargs)
  File "/mnt/cache/chencheng1/.local/lib/python3.6/site-packages/petrel_client/ceph/s3/s3_client.py", line 57, in get_with_info
    obj = self._s3_resource.Object(bucket, key).get(**get_kwargs)
  File "/mnt/cache/chencheng1/.local/lib/python3.6/site-packages/boto3/resources/factory.py", line 580, in do_action
    response = action(self, *args, **kwargs)
  File "/mnt/cache/chencheng1/.local/lib/python3.6/site-packages/boto3/resources/action.py", line 88, in __call__
    response = getattr(parent.meta.client, operation_name)(*args, **params)
  File "/mnt/cache/chencheng1/.local/lib/python3.6/site-packages/botocore/client.py", line 314, in _api_call
    return self._make_api_call(operation_name, kwargs)
  File "/mnt/cache/chencheng1/.local/lib/python3.6/site-packages/botocore/client.py", line 599, in _make_api_call
    operation_model, request_dict)
  File "/mnt/cache/chencheng1/.local/lib/python3.6/site-packages/botocore/endpoint.py", line 102, in make_request
    return self._send_request(request_dict, operation_model)
  File "/mnt/cache/chencheng1/.local/lib/python3.6/site-packages/botocore/endpoint.py", line 135, in _send_request
    success_response, exception):
  File "/mnt/cache/chencheng1/.local/lib/python3.6/site-packages/botocore/endpoint.py", line 202, in _needs_retry
    caught_exception=caught_exception, request_dict=request_dict)
  File "/mnt/cache/chencheng1/.local/lib/python3.6/site-packages/botocore/hooks.py", line 227, in emit
    return self._emit(event_name, kwargs)
  File "/mnt/cache/chencheng1/.local/lib/python3.6/site-packages/botocore/hooks.py", line 360, in _emit
    aliased_event_name, kwargs, stop_on_response
  File "/mnt/cache/chencheng1/.local/lib/python3.6/site-packages/botocore/hooks.py", line 210, in _emit
    response = handler(**kwargs)
  File "/mnt/cache/chencheng1/.local/lib/python3.6/site-packages/botocore/retryhandler.py", line 183, in __call__
    if self._checker(attempts, response, caught_exception):
  File "/mnt/cache/chencheng1/.local/lib/python3.6/site-packages/botocore/retryhandler.py", line 251, in __call__
    caught_exception)
  File "/mnt/cache/chencheng1/.local/lib/python3.6/site-packages/botocore/retryhandler.py", line 277, in _should_retry
    return self._checker(attempt_number, response, caught_exception)
  File "/mnt/cache/chencheng1/.local/lib/python3.6/site-packages/botocore/retryhandler.py", line 317, in __call__
    caught_exception)
  File "/mnt/cache/chencheng1/.local/lib/python3.6/site-packages/botocore/retryhandler.py", line 223, in __call__
    attempt_number, caught_exception)
  File "/mnt/cache/chencheng1/.local/lib/python3.6/site-packages/botocore/retryhandler.py", line 359, in _check_caught_exception
    raise caught_exception
  File "/mnt/cache/chencheng1/.local/lib/python3.6/site-packages/botocore/endpoint.py", line 173, in _get_response
    http_response = self._send(request)
  File "/mnt/cache/chencheng1/.local/lib/python3.6/site-packages/botocore/endpoint.py", line 215, in _send
    return self.http_session.send(request)
  File "/mnt/cache/chencheng1/.local/lib/python3.6/site-packages/botocore/httpsession.py", line 262, in send
    raise EndpointConnectionError(endpoint_url=request.url, error=e)
botocore.exceptions.EndpointConnectionError: Could not connect to the endpoint URL: "http://10.198.32.254:80/parsing_public/CIHP/instance-level_human_parsing/Validation/val_id.txt"
2022-10-31 16:27:28 5cab697d INFO: (pavi2.training) SummaryWriter now to close ... Flushing data ...
2022-10-31 16:27:28 9af7a8c3 SUCCESS: (pavi2.training) SummaryWriter is successfully closed

PAVI Info ###################################
Training：v100_32g_vitbase_size224_lr1e3_stepLRx3_bmp1_adafactor_wd01_clip05_layerdecay075_lpe_peddet_citypersons_LSA_reduct8_tbn1_heads2_gate1_peddetShareDecoder_exp3_setting_SharePosEmbed
Project：parsing_test
Training_id：123638
Training_url：http://autolink.parrots.sensetime.com/pages/content/project/3567/training/123638
Warning: If `Training_url` is not accessible, please upgrade your pavi version.
#############################################

phoenix-srun: error: SH-IDC1-10-198-4-246: task 0: Segmentation fault
